Workbook
Name solver_adj: 'Market Frontier'!$B$31
Name solver_cvg: 0.0001
Name solver_drv: 2
Name solver_eng: 1
Name solver_est: 1
Name solver_itr: 2147483647
Name solver_lhs1: 'Market Frontier'!$B$31
Name solver_lhs2: 'Market Frontier'!$B$31
Name solver_lhs3: 'Market Frontier'!$B$31:$B$32
Name solver_mip: 2147483647
Name solver_mni: 30
Name solver_mrt: 0.075
Name solver_msl: 2
Name solver_neg: 1
Name solver_nod: 2147483647
Name solver_num: 0
Name solver_nwt: 1
Name solver_opt: 'Market Frontier'!$B$35
Name solver_pre: 0.000001
Name solver_rbv: 2
Name solver_rel1: 1
Name solver_rel2: 3
Name solver_rel3: 2
Name solver_rhs1: 1
Name solver_rhs2: 0
Name solver_rhs3: 1
Name solver_rlx: 2
Name solver_rsd: 0
Name solver_scl: 2
Name solver_sho: 2
Name solver_ssz: 100
Name solver_tim: 2147483647
Name solver_tol: 0.01
Name solver_typ: 1
Name solver_val: 0
Name solver_ver: 3

Sheet Summary Report
A1: #VALUE! | G1: Total Marks
A3: Links to Annual Data and Charts | C3: Links | G3: 6
A4: 1.a | B4: Data - Yearly (format return) | C4: Data-Yearly
A5: 1.b | B5: Yearly Returns Chart | C5: Yearly Returns Chart
A6: 1.c | B6: Yearly Rescaled Price Chart | C6: Yearly Rescaled Price Chart
A8: Analysis of Annual Data | C8: USPH | D8: BG | G8: 8
A9: 1.d | B9: Buy and Hold Returns (2005-2025) | C9: 3.2279372 | D9: 0.57357359
A10: 1.e | B10: Compounded Annual Returns (2005-2025) | C10: 0.074747457 | D10: 0.022926319
A11: 1.f | B11: ="Number of years "& C8 &" beats "& D8 -> Number of years USPH beats BG | C11: 14
A12: 1.g | B12: Market frontier | C12: Market Frontier
A14: Link to Monthly Data | C14: Link | G14: 2
A15: 2.a | B15: Data - Monthly | C15: Data-Monthly
A17: Analysis of Monthly Data | C17: USPH | D17: BG | G17: 5
A18: 2.b | B18: Mean | C18: 0.011095016 | D18: 0.0065523234
B19: Median | C19: 0.011586719 | D19: 0.00744998
B20: Min | C20: -0.36536128 | D20: -0.39285468
B21: Max | C21: 0.33886416 | D21: 0.31784974
B22: Variance | C22: 0.0086356035 | D22: 0.007564516
B23: Standard Deviation | C23: 0.092927948 | D23: 0.086974226
B24: Kurtosis | C24: 1.6311829 | D24: 2.9047536
B25: Skewness | C25: -0.20587105 | D25: -0.14500233
A26: 2.c | B26: Month with the highest excess return | C26: 44165 | D26: 39964
B27: Month with the lowest excess return | C27: 44804 | D27: 39752
A29: Frequency Distributions of Excess Returns | C29: Link | G29: 2
A30: 2.d | B30: Frequency Distributions Charts | C30: Frequency Distributions Charts
A32: Correlation Matrix | C32: USPH | D32: BG | E32: Market | G32: 1
A33: 2.e | B33: USPH | C33: ='Data-Monthly'!L4 -> 1 | D33: ='Data-Monthly'!M4 -> 0.20706094 | E33: ='Data-Monthly'!N4 -> 0.56034915
B34: BG | C34: ='Data-Monthly'!L5 -> 0.20706094 | D34: ='Data-Monthly'!M5 -> 1 | E34: ='Data-Monthly'!N5 -> 0.43068717
B35: Market Returns | C35: ='Data-Monthly'!L6 -> 0.56034915 | D35: ='Data-Monthly'!M6 -> 0.43068717 | E35: ='Data-Monthly'!N6 -> 1
A37: Capital Asset Pricing Model | C37: USPH | D37: BG | G37: 6
A38: 2.f | B38: Alpha | C38: 0.0013575219 | D38: -0.00045245925
B39: Beta | C39: 1.1763542 | D39: 0.8462244
B40: Adj R-square | C40: 0.31123611 | D40: 0.18222032
B42: Presentation of the calculations, graphs and summary results | G42: 10
B44: Part I Total | G44: =SUM(G3:G42) -> 40

Sheet Data-Yearly
A1: Year (end) | B1: USPH_price | C1: BG_price | D1: Simple Return - USPH | E1: Simple Return - BG | F1: Rescaled Price - USPH | G1: Rescaled Price - BG
A2: 2005 | B2: 18.469999 | C2: 56.610001 | F2: =100 -> 100 | G2: =100 -> 100
A3: 2006 | B3: 12.25 | C3: 72.510002 | D3: =(B3/B2)-1 -> -0.33676229 | E3: =(C3/C2)-1 -> 0.28086913 | F3: =100*(B3/$B$2) -> 66.323771 | G3: =100*(C3/$C$2) -> 128.08691
A4: 2007 | B4: 14.37 | C4: 116.41 | D4: =(B4/B3)-1 -> 0.17306122 | E4: =(C4/C3)-1 -> 0.60543374 | F4: =100*(B4/$B$2) -> 77.801843 | G4: =100*(C4/$C$2) -> 205.63505
A5: 2008 | B5: 13.33 | C5: 51.77 | D5: =(B5/B4)-1 -> -0.072372997 | E5: =(C5/C4)-1 -> -0.55527877 | F5: =100*(B5/$B$2) -> 72.171091 | G5: =100*(C5/$C$2) -> 91.450274
A6: 2009 | B6: 16.93 | C6: 63.830002 | D6: =(B6/B5)-1 -> 0.27006755 | E6: =(C6/C5)-1 -> 0.23295347 | F6: =100*(B6/$B$2) -> 91.66216 | G6: =100*(C6/$C$2) -> 112.75393
A7: 2010 | B7: 19.82 | C7: 65.519997 | D7: =(B7/B6)-1 -> 0.17070286 | E7: =(C7/C6)-1 -> 0.026476496 | F7: =100*(B7/$B$2) -> 107.30915 | G7: =100*(C7/$C$2) -> 115.73926
A8: 2011 | B8: 19.68 | C8: 57.200001 | D8: =(B8/B7)-1 -> -0.0070635415 | E8: =(C8/C7)-1 -> -0.12698407 | F8: =100*(B8/$B$2) -> 106.55117 | G8: =100*(C8/$C$2) -> 101.04222
A9: 2012 | B9: 27.540001 | C9: 72.690002 | D9: =(B9/B8)-1 -> 0.39939027 | E9: =(C9/C8)-1 -> 0.27080422 | F9: =100*(B9/$B$2) -> 149.10667 | G9: =100*(C9/$C$2) -> 128.40488
A10: 2013 | B10: 35.259998 | C10: 82.110001 | D10: =(B10/B9)-1 -> 0.28031943 | E10: =(C10/C9)-1 -> 0.12959139 | F10: =100*(B10/$B$2) -> 190.90417 | G10: =100*(C10/$C$2) -> 145.04504
A11: 2014 | B11: 41.959999 | C11: 90.910004 | D11: =(B11/B10)-1 -> 0.19001705 | E11: =(C11/C10)-1 -> 0.10717334 | F11: =100*(B11/$B$2) -> 227.17921 | G11: =100*(C11/$C$2) -> 160.59001
A12: 2015 | B12: 53.68 | C12: 68.279999 | D12: =(B12/B11)-1 -> 0.27931367 | E12: =(C12/C11)-1 -> -0.24892755 | F12: =100*(B12/$B$2) -> 290.63347 | G12: =100*(C12/$C$2) -> 120.61473
A13: 2016 | B13: 70.199997 | C13: 72.239998 | D13: =(B13/B12)-1 -> 0.30774956 | E13: =(C13/C12)-1 -> 0.057996473 | F13: =100*(B13/$B$2) -> 380.0758 | G13: =100*(C13/$C$2) -> 127.60996
A14: 2017 | B14: 72.199997 | C14: 67.080002 | D14: =(B14/B13)-1 -> 0.02849003 | E14: =(C14/C13)-1 -> -0.071428519 | F14: =100*(B14/$B$2) -> 390.90417 | G14: =100*(C14/$C$2) -> 118.49497
... A22: 2025 | B22: 78.089996 | C22: 89.080002 | D22: =(B22/B21)-1 -> -0.11971596 | E22: =(C22/C21)-1 -> 0.14557612 | F22: =100*(B22/$B$2) -> 422.79372 | G22: =100*(C22/$C$2) -> 157.35736
A24: Buy and Hold Returns | B24: =(B22-B2)/B2 -> 3.2279372 | C24: =(C22-C2)/C2 -> 0.57357359
A25: Compounded Annual Returns | B25: =(B22/B2)^(1/20)-1 -> 0.074747457 | C25: =(C22/C2)^(1/20)-1 -> 0.022926319
A26: Years USPH beats BG | B26: {=+SUMPRODUCT((D3:D22>E3:E22)*1)} -> 14

Sheet Data-Monthly
A1: Month (end) | B1: USPH_price | C1: BG_price | D1: Montly Return USPH | E1: Montly Return BG | F1: Rm-Rf | G1: Rf | H1: USPH Excess Return | I1: BG Excess Return
A2: 38383 | B2: 11.608747 | C2: 35.874317 | F2: {='F-F_Research_Data_Factors'!B947:B1198} -> -0.0276 | G2: {=+'F-F_Research_Data_Factors'!C947:C1198} -> 0.0016 | K2: Correlation Matrix
A3: 38411 | B3: 10.944249 | C3: 34.713177 | D3: =(B3/B2)-1 -> -0.057241096 | E3: =(C3/C2)-1 -> -0.0323669 | F3: 0.0189 | G3: 0.0016 | H3: =D3-G3 -> -0.058841096 | I3: =E3-G3 -> -0.0339669 | L3: USPH | M3: BG | N3: Market
A4: 38442 | B4: 11.192434 | C4: 34.266888 | D4: =(B4/B3)-1 -> 0.022677221 | E4: =(C4/C3)-1 -> -0.012856474 | F4: -0.0197 | G4: 0.0021 | H4: =D4-G4 -> 0.020577221 | I4: =E4-G4 -> -0.014956474 | K4: USPH | L4: 1 | M4: =CORREL(H3:H253,I3:I253) -> 0.20706094 | N4: =CORREL(H3:H253,F3:F253) -> 0.56034915
A5: 38472 | B5: 11.552706 | C5: 36.123966 | D5: =(B5/B4)-1 -> 0.032188838 | E5: =(C5/C4)-1 -> 0.05419455 | F5: -0.0261 | G5: 0.0021 | H5: =D5-G5 -> 0.030088838 | I5: =E5-G5 -> 0.05209455 | K5: BG | L5: =CORREL(I3:I253,H3:H253) -> 0.20706094 | M5: 1 | N5: =CORREL(I3:I253,F3:F253) -> 0.43068717
A6: 38503 | B6: 12.833671 | C6: 39.456543 | D6: =(B6/B5)-1 -> 0.11088007 | E6: =(C6/C5)-1 -> 0.0922539 | F6: 0.0365 | G6: 0.0024 | H6: =D6-G6 -> 0.10848007 | I6: =E6-G6 -> 0.0898539 | K6: Market | L6: =CORREL(F3:F253,H3:H253) -> 0.56034915 | M6: =CORREL(F3:F253,I3:I253) -> 0.43068717 | N6: 1
A7: 38533 | B7: 15.355567 | C7: 40.414814 | D7: =(B7/B6)-1 -> 0.19650624 | E7: =(C7/C6)-1 -> 0.024286746 | F7: 0.0057 | G7: 0.0023 | H7: =D7-G7 -> 0.19420624 | I7: =E7-G7 -> 0.021986746
A8: 38564 | B8: 14.619019 | C8: 39.133518 | D8: =(B8/B7)-1 -> -0.047966215 | E8: =(C8/C7)-1 -> -0.031703617 | F8: 0.0392 | G8: 0.0024 | H8: =D8-G8 -> -0.050366215 | I8: =E8-G8 -> -0.034103617 | K8: Capital Asset Pricing Model for USPH
A9: 38595 | B9: 15.115384 | C9: 37.431496 | D9: =(B9/B8)-1 -> 0.033953411 | E9: =(C9/C8)-1 -> -0.043492705 | F9: -0.0122 | G9: 0.003 | H9: =D9-G9 -> 0.030953411 | I9: =E9-G9 -> -0.046492705 | K9: Alpha | L9: =L28 -> 0.0013575219
A10: 38625 | B10: 14.538955 | C10: 33.629169 | D10: =(B10/B9)-1 -> -0.038135277 | E10: =(C10/C9)-1 -> -0.10158093 | F10: 0.0049 | G10: 0.0029 | H10: =D10-G10 -> -0.041035277 | I10: =E10-G10 -> -0.10448093 | K10: Beta | L10: =L29 -> 1.1763542
A11: 38656 | B11: 14.426865 | C11: 33.19458 | D11: =(B11/B10)-1 -> -0.0077096403 | E11: =(C11/C10)-1 -> -0.012922989 | F11: -0.0202 | G11: 0.0027 | H11: =D11-G11 -> -0.01040964 | I11: =E11-G11 -> -0.015622989 | K11: Adjusted R square | L11: =L17 -> 0.31123611
A12: 38686 | B12: 15.843942 | C12: 34.19157 | D12: =(B12/B11)-1 -> 0.098224881 | E12: =(C12/C11)-1 -> 0.030034729 | F12: 0.0361 | G12: 0.0031 | H12: =D12-G12 -> 0.095124881 | I12: =E12-G12 -> 0.026934729 | K12: SUMMARY OUTPUT
A13: 38717 | B13: 14.787141 | C13: 36.284897 | D13: =(B13/B12)-1 -> -0.066700627 | E13: =(C13/C12)-1 -> 0.06122347 | F13: -0.0025 | G13: 0.0032 | H13: =D13-G13 -> -0.069900627 | I13: =E13-G13 -> 0.05802347
A14: 38748 | B14: 14.891226 | C14: 37.791168 | D14: =(B14/B13)-1 -> 0.007038884 | E14: =(C14/C13)-1 -> 0.041512351 | F14: 0.0304 | G14: 0.0035 | H14: =D14-G14 -> 0.003538884 | I14: =E14-G14 -> 0.038012351 | K14: Regression Statistics
A15: 38776 | B15: 15.411613 | C15: 36.33617 | D15: =(B15/B14)-1 -> 0.03494586 | E15: =(C15/C14)-1 -> -0.038501007 | F15: -0.003 | G15: 0.0034 | H15: =D15-G15 -> 0.03154586 | I15: =E15-G15 -> -0.041901007 | K15: Multiple R | L15: 0.56034915
A16: 38807 | B16: 13.698325 | C16: 35.803135 | D16: =(B16/B15)-1 -> -0.1111686 | E16: =(C16/C15)-1 -> -0.01466955 | F16: 0.0146 | G16: 0.0037 | H16: =D16-G16 -> -0.1148686 | I16: =E16-G16 -> -0.01836955 | K16: R Square | L16: 0.31399117
A17: 38837 | B17: 12.513428 | C17: 34.286438 | D17: =(B17/B16)-1 -> -0.086499438 | E17: =(C17/C16)-1 -> -0.042362126 | F17: 0.0073 | G17: 0.0036 | H17: =D17-G17 -> -0.090099438 | I17: =E17-G17 -> -0.045962126 | K17: Adjusted R Square | L17: 0.31123611
A18: 38868 | B18: 12.033064 | C18: 36.375118 | D18: =(B18/B17)-1 -> -0.038387871 | E18: =(C18/C17)-1 -> 0.060918555 | F18: -0.0357 | G18: 0.0043 | H18: =D18-G18 -> -0.042687871 | I18: =E18-G18 -> 0.056618555 | K18: Standard Error | L18: 0.077122577
A19: 38898 | B19: 11.720831 | C19: 32.376686 | D19: =(B19/B18)-1 -> -0.025947919 | E19: =(C19/C18)-1 -> -0.10992218 | F19: -0.0035 | G19: 0.004 | H19: =D19-G19 -> -0.029947919 | I19: =E19-G19 -> -0.11392218 | K19: Observations | L19: 251
A20: 38929 | B20: 12.241223 | C20: 35.166576 | D20: =(B20/B19)-1 -> 0.044398936 | E20: =(C20/C19)-1 -> 0.08616973 | F20: -0.0078 | G20: 0.004 | H20: =D20-G20 -> 0.040398936 | I20: =E20-G20 -> 0.08216973
A21: 38960 | B21: 11.712826 | C21: 36.30056 | D21: =(B21/B20)-1 -> -0.043165421 | E21: =(C21/C20)-1 -> 0.032246062 | F21: 0.0203 | G21: 0.0042 | H21: =D21-G21 -> -0.047365421 | I21: =E21-G21 -> 0.028046062 | K21: ANOVA
A22: 38990 | B22: 9.5431929 | C22: 37.44973 | D22: =(B22/B21)-1 -> -0.18523565 | E22: =(C22/C21)-1 -> 0.031657085 | F22: 0.0184 | G22: 0.0041 | H22: =D22-G22 -> -0.18933565 | I22: =E22-G22 -> 0.027557085 | L22: df | M22: SS | N22: MS | O22: F | P22: Significance F
A23: 39021 | B23: 9.6472731 | C23: 41.430588 | D23: =(B23/B22)-1 -> 0.010906224 | E23: =(C23/C22)-1 -> 0.10629871 | F23: 0.0323 | G23: 0.0041 | H23: =D23-G23 -> 0.0068062241 | I23: =E23-G23 -> 0.10219871 | K23: Regression | L23: 1 | M23: 0.6778758 | N23: 0.6778758 | O23: 113.96909 | P23: 3.7522549e-22
A24: 39051 | B24: 9.383069 | C24: 45.560074 | D24: =(B24/B23)-1 -> -0.027386394 | E24: =(C24/C23)-1 -> 0.099672399 | F24: 0.0171 | G24: 0.0042 | H24: =D24-G24 -> -0.031586394 | I24: =E24-G24 -> 0.095472399 | K24: Residual | L24: 249 | M24: 1.4810251 | N24: 0.0059478919
A25: 39082 | B25: 9.8073893 | C25: 46.970352 | D25: =(B25/B24)-1 -> 0.045221901 | E25: =(C25/C24)-1 -> 0.030954259 | F25: 0.0087 | G25: 0.004 | H25: =D25-G25 -> 0.041221901 | I25: =E25-G25 -> 0.026954259 | K25: Total | L25: 250 | M25: 2.1589009
A26: 39113 | B26: 11.288507 | C26: 49.846493 | D26: =(B26/B25)-1 -> 0.15102064 | E26: =(C26/C25)-1 -> 0.061233107 | F26: 0.014 | G26: 0.0044 | H26: =D26-G26 -> 0.14662064 | I26: =E26-G26 -> 0.056833107
A27: 39141 | B27: 10.816154 | C27: 51.349327 | D27: =(B27/B26)-1 -> -0.04184379 | E27: =(C27/C26)-1 -> 0.030149249 | F27: -0.0196 | G27: 0.0038 | H27: =D27-G27 -> -0.04564379 | I27: =E27-G27 -> 0.026349249 | L27: Coefficients | M27: Standard Error | N27: t Stat | O27: P-value | P27: Lower 95% | Q27: Upper 95% | R27: Lower 95.0% | S27: Upper 95.0%
A28: 39172 | B28: 11.1444 | C28: 53.366791 | D28: =(B28/B27)-1 -> 0.030347768 | E28: =(C28/C27)-1 -> 0.039288999 | F28: 0.0068 | G28: 0.0043 | H28: =D28-G28 -> 0.026047768 | I28: =E28-G28 -> 0.034988999 | K28: Intercept | L28: 0.0013575219 | M28: 0.0049526508 | N28: 0.27410006 | O28: 0.78423498 | P28: -0.0083969064 | Q28: 0.01111195 | R28: -0.0083969064 | S28: 0.01111195
A29: 39202 | B29: 11.68881 | C29: 49.173779 | D29: =(B29/B28)-1 -> 0.048850609 | E29: =(C29/C28)-1 -> -0.078569691 | F29: 0.0349 | G29: 0.0044 | H29: =D29-G29 -> 0.044450609 | I29: =E29-G29 -> -0.082969691 | K29: X Variable 1 | L29: 1.1763542 | M29: 0.1101906 | N29: 10.67563 | O29: 3.7522549e-22 | P29: 0.95932971 | Q29: 1.3933786 | R29: 0.95932971 | S29: 1.3933786
A30: 39233 | B30: 11.120382 | C30: 50.705601 | D30: =(B30/B29)-1 -> -0.048630102 | E30: =(C30/C29)-1 -> 0.0311512 | F30: 0.0324 | G30: 0.0041 | H30: =D30-G30 -> -0.052730102 | I30: =E30-G30 -> 0.0270512
A31: 39263 | B31: 10.784128 | C31: 54.969154 | D31: =(B31/B30)-1 -> -0.03023764 | E31: =(C31/C30)-1 -> 0.084084471 | F31: -0.0196 | G31: 0.004 | H31: =D31-G31 -> -0.03423764 | I31: =E31-G31 -> 0.080084471
A32: 39294 | B32: 10.896213 | C32: 58.943844 | D32: =(B32/B31)-1 -> 0.010393458 | E32: =(C32/C31)-1 -> 0.072307634 | F32: -0.0373 | G32: 0.004 | H32: =D32-G32 -> 0.0063934585 | I32: =E32-G32 -> 0.068307634 | K32: Capital Asset Pricing Model for BG
A33: 39325 | B33: 11.008294 | C33: 59.483761 | D33: =(B33/B32)-1 -> 0.010286283 | E33: =(C33/C32)-1 -> 0.0091598538 | F33: 0.0092 | G33: 0.0042 | H33: =D33-G33 -> 0.0060862831 | I33: =E33-G33 -> 0.0049598538 | K33: Alpha | L33: =L52 -> -0.00045245925
A34: 39355 | B34: 11.848927 | C34: 70.0383 | D34: =(B34/B33)-1 -> 0.076363639 | E34: =(C34/C33)-1 -> 0.17743563 | F34: 0.0322 | G34: 0.0032 | H34: =D34-G34 -> 0.073163639 | I34: =E34-G34 -> 0.17423563 | K34: Beta | L34: =L53 -> 0.8462244
A35: 39386 | B35: 11.736847 | C35: 75.08345 | D35: =(B35/B34)-1 -> -0.0094591324 | E35: =(C35/C34)-1 -> 0.07203417 | F35: 0.018 | G35: 0.0032 | H35: =D35-G35 -> -0.012659132 | I35: =E35-G35 -> 0.06883417 | K35: Adjusted R square | L35: =L41 -> 0.18222032
A36: 39416 | B36: 10.99228 | C36: 73.225754 | D36: =(B36/B35)-1 -> -0.063438411 | E36: =(C36/C35)-1 -> -0.024741758 | F36: -0.0483 | G36: 0.0034 | H36: =D36-G36 -> -0.066838411 | I36: =E36-G36 -> -0.028141758 | K36: SUMMARY OUTPUT
A37: 39447 | B37: 11.50467 | C37: 75.996078 | D37: =(B37/B36)-1 -> 0.046613636 | E37: =(C37/C36)-1 -> 0.037832655 | F37: -0.0087 | G37: 0.0027 | H37: =D37-G37 -> 0.043913636 | I37: =E37-G37 -> 0.035132655
A38: 39478 | B38: 10.728087 | C38: 76.400841 | D38: =(B38/B37)-1 -> -0.06750152 | E38: =(C38/C37)-1 -> 0.0053260941 | F38: -0.0636 | G38: 0.0021 | H38: =D38-G38 -> -0.06960152 | I38: =E38-G38 -> 0.0032260941 | K38: Regression Statistics
A39: 39507 | B39: 10.607993 | C39: 72.35981 | D39: =(B39/B38)-1 -> -0.011194381 | E39: =(C39/C38)-1 -> -0.052892492 | F39: -0.0309 | G39: 0.0013 | H39: =D39-G39 -> -0.012494381 | I39: =E39-G39 -> -0.054192492 | K39: Multiple R | L39: 0.43068717
A40: 39538 | B40: 11.544698 | C40: 56.802994 | D40: =(B40/B39)-1 -> 0.088301776 | E40: =(C40/C39)-1 -> -0.2149925 | F40: -0.0093 | G40: 0.0017 | H40: =D40-G40 -> 0.086601776 | I40: =E40-G40 -> -0.2166925 | K40: R Square | L40: 0.18549144
...

Sheet Yearly Returns Chart
A1: 'Yearly Returns Chart

Sheet Yearly Rescaled Price Chart 
A1: 'Yearly Rescaled Price Chart '!A1

Sheet Market Frontier
A1: Inputs | B1: USPH | C1: BG | D1: Risk | E1: Return
A2: Mean Return | B2: =AVERAGE('Data-Yearly'!D3:D22) -> 0.094707396 | C2: =AVERAGE('Data-Yearly'!E3:E22) -> 0.057086446 | D2: 0 | E2: =B5 -> 0.04
A3: Standard Deviation | B3: =_xlfn.STDEV.S('Data-Yearly'!D3:D22) -> 0.20699251 | C3: =_xlfn.STDEV.S('Data-Yearly'!E3:E22) -> 0.2571833 | D3: =B34 -> 0.17198977 | E3: =B33 -> 0.087462129
A4: Correlation | B4: =CORREL('Data-Yearly'!D3:D22,'Data-Yearly'!E3:E22) -> -0.048606701
A5: Risk free rate (given) | B5: =4% -> 0.04
A7: Weight USPH | B7: Weight BG | C7: Portfolio Return | D7: Portfolio Standard Deviation
A8: 0 | B8: =1-A8 -> 1 | C8: =(A8*$B$2)+(B8*$C$2) -> 0.057086446 | D8: =SQRT(A8^2*$B$3^2+B8^2*$C$3^2+2*A8*B8*$B$3*$C$3*$B$4) -> 0.2571833
A9: =A8+0.05 -> 0.05 | B9: =1-A9 -> 0.95 | C9: =(A9*$B$2)+(B9*$C$2) -> 0.058967494 | D9: =SQRT(A9^2*$B$3^2+B9^2*$C$3^2+2*A9*B9*$B$3*$C$3*$B$4) -> 0.24404011
A10: =A9+0.05 -> 0.1 | B10: =1-A10 -> 0.9 | C10: =(A10*$B$2)+(B10*$C$2) -> 0.060848541 | D10: =SQRT(A10^2*$B$3^2+B10^2*$C$3^2+2*A10*B10*$B$3*$C$3*$B$4) -> 0.23138437
A11: =A10+0.05 -> 0.15 | B11: =1-A11 -> 0.85 | C11: =(A11*$B$2)+(B11*$C$2) -> 0.062729589 | D11: =SQRT(A11^2*$B$3^2+B11^2*$C$3^2+2*A11*B11*$B$3*$C$3*$B$4) -> 0.21930047
A12: =A11+0.05 -> 0.2 | B12: =1-A12 -> 0.8 | C12: =(A12*$B$2)+(B12*$C$2) -> 0.064610636 | D12: =SQRT(A12^2*$B$3^2+B12^2*$C$3^2+2*A12*B12*$B$3*$C$3*$B$4) -> 0.20788817
A13: =A12+0.05 -> 0.25 | B13: =1-A13 -> 0.75 | C13: =(A13*$B$2)+(B13*$C$2) -> 0.066491684 | D13: =SQRT(A13^2*$B$3^2+B13^2*$C$3^2+2*A13*B13*$B$3*$C$3*$B$4) -> 0.19726405
A14: =A13+0.05 -> 0.3 | B14: =1-A14 -> 0.7 | C14: =(A14*$B$2)+(B14*$C$2) -> 0.068372731 | D14: =SQRT(A14^2*$B$3^2+B14^2*$C$3^2+2*A14*B14*$B$3*$C$3*$B$4) -> 0.1875621
A15: =A14+0.05 -> 0.35 | B15: =1-A15 -> 0.65 | C15: =(A15*$B$2)+(B15*$C$2) -> 0.070253779 | D15: =SQRT(A15^2*$B$3^2+B15^2*$C$3^2+2*A15*B15*$B$3*$C$3*$B$4) -> 0.17893238
A16: =A15+0.05 -> 0.4 | B16: =1-A16 -> 0.6 | C16: =(A16*$B$2)+(B16*$C$2) -> 0.072134826 | D16: =SQRT(A16^2*$B$3^2+B16^2*$C$3^2+2*A16*B16*$B$3*$C$3*$B$4) -> 0.17153681
A17: =A16+0.05 -> 0.45 | B17: =1-A17 -> 0.55 | C17: =(A17*$B$2)+(B17*$C$2) -> 0.074015873 | D17: =SQRT(A17^2*$B$3^2+B17^2*$C$3^2+2*A17*B17*$B$3*$C$3*$B$4) -> 0.16554086
A18: =A17+0.05 -> 0.5 | B18: =1-A18 -> 0.5 | C18: =(A18*$B$2)+(B18*$C$2) -> 0.075896921 | D18: =SQRT(A18^2*$B$3^2+B18^2*$C$3^2+2*A18*B18*$B$3*$C$3*$B$4) -> 0.16110089
A19: =A18+0.05 -> 0.55 | B19: =1-A19 -> 0.45 | C19: =(A19*$B$2)+(B19*$C$2) -> 0.077777968 | D19: =SQRT(A19^2*$B$3^2+B19^2*$C$3^2+2*A19*B19*$B$3*$C$3*$B$4) -> 0.15834785
A20: =A19+0.05 -> 0.6 | B20: =1-A20 -> 0.4 | C20: =(A20*$B$2)+(B20*$C$2) -> 0.079659016 | D20: =SQRT(A20^2*$B$3^2+B20^2*$C$3^2+2*A20*B20*$B$3*$C$3*$B$4) -> 0.15737028
... A28: =A27+0.05 -> 1 | B28: =1-A28 -> 0 | C28: =(A28*$B$2)+(B28*$C$2) -> 0.094707396 | D28: =SQRT(A28^2*$B$3^2+B28^2*$C$3^2+2*A28*B28*$B$3*$C$3*$B$4) -> 0.20699251
A31: Optimal Weight USPH | B31: 0.80741404
A32: Optimal Weight BG | B32: =1-B31 -> 0.19258596
A33: Optimal Portfolio Return | B33: =(B31*$B$2)+(B32*$C$2) -> 0.087462129
A34: Optimal Standard Deviation | B34: =SQRT((B31^2*$B$3^2)+(B32^2*$C$3^2)+(2*B31*B32*$B$3*$C$3*$B$4)) -> 0.17198977
A35: Optimal Sharpe Ratio | B35: =(B33-$B$5)/B34 -> 0.27595903

Sheet Frequency Distributions Charts
A1: USPH | D1: BG
A2: Bin | B2: Frequency | D2: Bin | E2: Frequency
A3: -0.36546128 | B3: 0 | D3: -0.39295468 | E3: 0
A4: -0.34198043 | B4: 1 | D4: -0.36925786 | E4: 1
A5: -0.31849959 | B5: 1 | D5: -0.34556105 | E5: 0
A6: -0.29501874 | B6: 0 | D6: -0.32186423 | E6: 0
A7: -0.27153789 | B7: 0 | D7: -0.29816742 | E7: 0
A8: -0.24805704 | B8: 0 | D8: -0.27447061 | E8: 1
A9: -0.22457619 | B9: 0 | D9: -0.25077379 | E9: 0
A10: -0.20109535 | B10: 2 | D10: -0.22707698 | E10: 1
A11: -0.1776145 | B11: 1 | D11: -0.20338016 | E11: 1
A12: -0.15413365 | B12: 3 | D12: -0.17968335 | E12: 1
A13: -0.1306528 | B13: 5 | D13: -0.15598654 | E13: 2
A14: -0.10717195 | B14: 9 | D14: -0.13228972 | E14: 3
... A33: 0.33896416 | B33: 1 | D33: 0.31794974 | E33: 2
A34: More | B34: 0 | D34: More | E34: 0

Sheet T-Test Full Sample
A2: T-Test Analysis of Monthly Returns
A3: t-Test: Two-Sample Assuming Unequal Variances
B5: Variable 1 | C5: Variable 2
A6: Mean | B6: 0.011133914 | C6: 0.0056652803
A7: Variance | B7: 0.0086752765 | C7: 0.0075516793
A8: Observations | B8: 251 | C8: 251
A9: Hypothesized Mean Difference | B9: 0
A10: df | B10: 498
A11: t Stat | B11: 0.68013819
A12: P(T<=t) one-tail | B12: 0.24836651
A13: t Critical one-tail | B13: 1.6479191
A14: P(T<=t) two-tail | B14: 0.49673302
A15: t Critical two-tail | B15: 1.964739

Sheet T-Test Bull Market 
A2: Month (end) | B2: Montly Return USPH | C2: Montly Return BG
A3: 39903 | B3: -0.056530206 | C3: 0.20840444 | E3: Bull Market Analysis (March 2009 – February 2020)
A4: 39933 | B4: 0.20661156 | C4: -0.1525155 | E4: t-Test: Two-Sample Assuming Unequal Variances
A5: 39964 | B5: 0.15667807 | C5: 0.3178505
A6: 39994 | B6: 0.091783845 | C6: -0.047731949 | F6: Variable 1 | G6: Variable 2
A7: 40025 | B7: 0.1084746 | C7: 0.16132782 | E7: Mean | F7: 0.020874526 | G7: 0.0027940077
A8: 40056 | B8: -0.1119266 | C8: -0.042303831 | E8: Variance | F8: 0.0064335731 | G8: 0.0057683507
A9: 40086 | B9: 0.037878734 | C9: -0.065661862 | E9: Observations | F9: 132 | G9: 132
A10: 40117 | B10: -0.068347694 | C10: -0.088643974 | E10: Hypothesized Mean Difference | F10: 0
A11: 40147 | B11: 0.040598269 | C11: 0.084822994 | E11: df | F11: 261
A12: 40178 | B12: 0.15879539 | C12: 0.031179326 | E12: t Stat | F12: 1.8805448
A13: 40209 | B13: -0.075014792 | C13: -0.078959749 | E13: P(T<=t) one-tail | F13: 0.030573663
A14: 40237 | B14: 0.047254137 | C14: 0.013607743 | E14: t Critical one-tail | F14: 1.6507127
A15: 40268 | B15: 0.060975611 | C15: 0.034233947 | E15: P(T<=t) two-tail | F15: 0.061147325
A16: 40298 | B16: 0.0080460517 | C16: -0.1408405 | E16: t Critical two-tail | F16: 1.9690947
A17: 40329 | B17: -0.048460681 | C17: -0.079131301
A18: 40359 | B18: 0.01138398 | C18: 0.0088187104
A19: 40390 | B19: 0.07760672 | C19: 0.0093515534
A20: 40421 | B20: -0.11874655 | C20: 0.067472273
A21: 40451 | B21: 0.043044204 | C21: 0.11622641
A22: 40482 | B22: 0.12260773 | C22: 0.015382012
A23: 40512 | B23: 0.022376136 | C23: 0.012485434
A24: 40543 | B24: 0.032829554 | C24: 0.077277162
A25: 40574 | B25: -0.041372336 | C25: 0.038919462
A26: 40602 | B26: 0.04052634 | C26: 0.060232092
A27: 40633 | B27: 0.12999492 | C27: 0.0022170385
A28: 40663 | B28: 0.089973152 | C28: 0.042997381
... A134: 43890 | B134: -0.11029536 | C134: -0.1045203

Sheet CAPM Bull Market
A1: Bull Market Analysis (March 2009 – February 2020)
A2: Month (end) | B2: Rm-Rf | C2: USPH Excess Return | D2: BG Excess Return
A3: 39903 | B3: 0.0895 | C3: -0.056730206 | D3: 0.20820444 | G3: Capital Asset Pricing Model for USPH (Bull Market)
A4: 39933 | B4: 0.1018 | C4: 0.20651156 | D4: -0.1526155 | G4: Alpha | H4: =H23 -> 0.0079386226
A5: 39964 | B5: 0.0521 | C5: 0.15667807 | D5: 0.3178505 | G5: Beta | H5: =H24 -> 0.98190631
A6: 39994 | B6: 0.0043 | C6: 0.091683845 | D6: -0.047831949 | G6: Adjusted R square | H6: =H12 -> 0.22347851
A7: 40025 | B7: 0.0772 | C7: 0.1083746 | D7: 0.16122782 | G7: SUMMARY OUTPUT
A8: 40056 | B8: 0.0333 | C8: -0.1120266 | D8: -0.042403831
A9: 40086 | B9: 0.0408 | C9: 0.037778734 | D9: -0.065761862 | G9: Regression Statistics
A10: 40117 | B10: -0.0259 | C10: -0.068347694 | D10: -0.088643974 | G10: Multiple R | H10: 0.47896363
A11: 40147 | B11: 0.0556 | C11: 0.040598269 | D11: 0.084822994 | G11: R Square | H11: 0.22940615
A12: 40178 | B12: 0.0275 | C12: 0.15869539 | D12: 0.031079326 | G12: Adjusted R Square | H12: 0.22347851
A13: 40209 | B13: -0.0336 | C13: -0.075014792 | D13: -0.078959749 | E13: =INTERCEPT(C3:C134,B3:B134) -> 0.0079386226 | G13: Standard Error | H13: 0.070695401
A14: 40237 | B14: 0.034 | C14: 0.047254137 | D14: 0.013607743 | G14: Observations | H14: 132
A15: 40268 | B15: 0.0631 | C15: 0.060875611 | D15: 0.034133947
A16: 40298 | B16: 0.02 | C16: 0.0079460517 | D16: -0.1409405 | G16: ANOVA
A17: 40329 | B17: -0.0789 | C17: -0.048560681 | D17: -0.079231301 | H17: df | I17: SS | J17: MS | K17: F | L17: Significance F
A18: 40359 | B18: -0.0557 | C18: 0.01128398 | D18: 0.0087187104 | G18: Regression | H18: 1 | I18: 0.19342171 | J18: 0.19342171 | K18: 38.701062 | L18: 6.2669673e-09
A19: 40390 | B19: 0.0693 | C19: 0.07750672 | D19: 0.0092515534 | G19: Residual | H19: 130 | I19: 0.64971917 | J19: 0.0049978398
A20: 40421 | B20: -0.0477 | C20: -0.11884655 | D20: 0.067372273 | G20: Total | H20: 131 | I20: 0.84314088
A21: 40451 | B21: 0.0954 | C21: 0.042944204 | D21: 0.11612641
A22: 40482 | B22: 0.0388 | C22: 0.12250773 | D22: 0.015282012 | H22: Coefficients | I22: Standard Error | J22: t Stat | K22: P-value | L22: Lower 95% | M22: Upper 95% | N22: Lower 95.0% | O22: Upper 95.0%
A23: 40512 | B23: 0.006 | C23: 0.022276136 | D23: 0.012385434 | G23: Intercept | H23: 0.0079386226 | I23: 0.0064741537 | J23: 1.2262024 | K23: 0.22233901 | L23: -0.0048697163 | M23: 0.020746961 | N23: -0.0048697163 | O23: 0.020746961
A24: 40543 | B24: 0.0682 | C24: 0.032729554 | D24: 0.077177162 | G24: X Variable 1 | H24: 0.98190631 | I24: 0.15783692 | J24: 6.2210177 | K24: 6.2669673e-09 | L24: 0.66964483 | M24: 1.2941678 | N24: 0.66964483 | O24: 1.2941678
A25: 40574 | B25: 0.0199 | C25: -0.041472336 | D25: 0.038819462 | G25: Capital Asset Pricing Model for BG(Bull Market)
A26: 40602 | B26: 0.0349 | C26: 0.04042634 | D26: 0.060132092 | G26: Alpha | H26: =H45 -> -0.0091242426
A27: 40633 | B27: 0.0046 | C27: 0.12989492 | D27: 0.0021170385 | G27: Beta | H27: =H46 -> 0.90211407
A28: 40663 | B28: 0.029 | C28: 0.089973152 | D28: 0.042997381 | G28: Adjusted R square | H28: =H34 -> 0.20962371
A29: 40694 | B29: -0.0127 | C29: 0.057084163 | D29: -0.013123084 | G29: SUMMARY OUTPUT
A30: 40724 | B30: -0.0175 | C30: -0.039238548 | D30: -0.073875087
A31: 40755 | B31: -0.0235 | C31: -0.026283851 | D31: -0.0020304481 | G31: Regression Statistics
A32: 40786 | B32: -0.0599 | C32: -0.17534914 | D32: -0.059684343 | G32: Multiple R | H32: 0.46438897
A33: 40816 | B33: -0.0759 | C33: -0.067472312 | D33: -0.099211841 | G33: R Square | H33: 0.21565711
A34: 40847 | B34: 0.1135 | C34: 0.053995679 | D34: 0.059701484 | G34: Adjusted R Square | H34: 0.20962371
A35: 40877 | B35: -0.0028 | C35: 0.0076844065 | D35: 0.011818027 | G35: Standard Error | H35: 0.067583927
A36: 40908 | B36: 0.0074 | C36: 0.00050840004 | D36: -0.084799988 | G36: Observations | H36: 132
A37: 40939 | B37: 0.0505 | C37: 0.03658533 | D37: 0.0012237709
A38: 40968 | B38: 0.0442 | C38: -0.068137226 | D38: 0.17548453 | G38: ANOVA
A39: 40999 | B39: 0.0311 | C39: 0.21251967 | D39: 0.016636999 | H39: df | I39: SS | J39: MS | K39: F | L39: Significance F
A40: 41029 | B40: -0.0085 | C40: 0.057700649 | D40: -0.057568707 | G40: Regression | H40: 1 | I40: 0.16326309 | J40: 0.16326309 | K40: 35.743838 | L40: 2.0365356e-08
...

Sheet T-Test Bear Market
A2: Month (end) | B2: Montly Return USPH | C2: Montly Return BG | E2: Bear Market Analysis (Jan 2022 – Dec 2022)
A3: 44592 | B3: 0.012768117 | C3: 0.058911739 | E3: t-Test: Two-Sample Assuming Unequal Variances
A4: 44620 | B4: -0.049602104 | C4: 0.057556164
A5: 44651 | B5: 0.081330821 | C5: 0.059875603 | F5: Variable 1 | G5: Variable 2
A6: 44681 | B6: 0.043438912 | C6: 0.020846541 | E6: Mean | F6: -0.0027510001 | G6: 0.011967887
A7: 44712 | B7: 0.084995663 | C7: 0.045968855 | E7: Variance | F7: 0.020546692 | G7: 0.013084806
A8: 44742 | B8: -0.030109241 | C8: -0.23351925 | E8: Observations | F8: 12 | G8: 12
A9: 44773 | B9: 0.18846156 | C9: 0.018083574 | E9: Hypothesized Mean Difference | F9: 0
A10: 44804 | B10: -0.36346123 | C10: 0.074082056 | E10: df | F10: 21
A11: 44834 | B11: -0.079772472 | C11: -0.16738932 | E11: t Stat | F11: -0.27803052
A12: 44865 | B12: 0.16811375 | C12: 0.19534937 | E12: P(T<=t) one-tail | F12: 0.39185397
A13: 44895 | B13: -0.026914407 | C13: 0.062208709 | E13: t Critical one-tail | F13: 1.7207429
A14: 44926 | B14: -0.062261366 | C14: -0.048359404 | E14: P(T<=t) two-tail | F14: 0.78370794
E15: t Critical two-tail | F15: 2.0796138

Sheet CAPM Bear Market
A1: Bear Market Analysis (January 2022 – December 2022)
A2: Month (end) | B2: Rm-Rf | C2: USPH Excess Return | D2: BG Excess Return | G2: Capital Asset Pricing Model for USPH (Bear Market)
A3: 44592 | B3: -0.0625 | C3: 0.012768117 | D3: 0.058911739 | G3: Alpha | H3: =H23 -> 0.015935
A4: 44620 | B4: -0.0229 | C4: -0.049602104 | D4: 0.057556164 | G4: Beta | H4: =H24 -> 1.122033
A5: 44651 | B5: 0.0305 | C5: 0.081230821 | D5: 0.059775603 | G5: Adjusted R square | H5: =H12 -> 0.20090771
A6: 44681 | B6: -0.0946 | C6: 0.043338912 | D6: 0.020746541
A7: 44712 | B7: -0.0034 | C7: 0.084695663 | D7: 0.045668855 | G7: SUMMARY OUTPUT
A8: 44742 | B8: -0.0843 | C8: -0.030709241 | D8: -0.23411925
A9: 44773 | B9: 0.0957 | C9: 0.18766156 | D9: 0.017283574 | G9: Regression Statistics
A10: 44804 | B10: -0.0377 | C10: -0.36536123 | D10: 0.072182056 | G10: Multiple R | H10: 0.52302243
A11: 44834 | B11: -0.0935 | C11: -0.081672472 | D11: -0.16928932 | G11: R Square | H11: 0.27355247
A12: 44865 | B12: 0.0783 | C12: 0.16581375 | D12: 0.19304937 | G12: Adjusted R Square | H12: 0.20090771
A13: 44895 | B13: 0.046 | C13: -0.029814407 | D13: 0.059308709 | G13: Standard Error | H13: 0.12843975
A14: 44926 | B14: -0.0641 | C14: -0.065561366 | D14: -0.051659404 | G14: Observations | H14: 12
G16: ANOVA
H17: df | I17: SS | J17: MS | K17: F | L17: Significance F
G18: Regression | H18: 1 | I18: 0.062120548 | J18: 0.062120548 | K18: 3.765619 | L18: 0.0810111
G19: Residual | H19: 10 | I19: 0.16496769 | J19: 0.016496769
G20: Total | H20: 11 | I20: 0.22708824
H22: Coefficients | I22: Standard Error | J22: t Stat | K22: P-value | L22: Lower 95% | M22: Upper 95% | N22: Lower 95.0% | O22: Upper 95.0%
G23: Intercept | H23: 0.015935 | I23: 0.038465199 | J23: 0.41427058 | K23: 0.68742199 | L23: -0.069770804 | M23: 0.1016408 | N23: -0.069770804 | O23: 0.1016408
G24: X Variable 1 | H24: 1.122033 | I24: 0.57821243 | J24: 1.9405203 | K24: 0.0810111 | L24: -0.16630462 | M24: 2.4103705 | N24: -0.16630462 | O24: 2.4103705
G26: Capital Asset Pricing Model for BG (Bear Market)
G27: Alpha | H27: =H23 -> 0.015935
G28: Beta | H28: =H24 -> 1.122033
G29: Adjusted R square | H29: =H12 -> 0.20090771
G30: SUMMARY OUTPUT
G32: Regression Statistics
G33: Multiple R | H33: 0.62479659
G34: R Square | H34: 0.39037077
G35: Adjusted R Square | H35: 0.32940785
G36: Standard Error | H36: 0.093665469
G37: Observations | H37: 12
G39: ANOVA
H40: df | I40: SS | J40: MS | K40: F | L40: Significance F
G41: Regression | H41: 1 | I41: 0.056178552 | J41: 0.056178552 | K41: 6.403413 | L41: 0.029845482
G42: Residual | H42: 10 | I42: 0.087732202 | J42: 0.0087732202
G43: Total | H43: 11 | I43: 0.14391075
H45: Coefficients | I45: Standard Error | J45: t Stat | K45: P-value | L45: Lower 95% | M45: Upper 95% | N45: Lower 95.0% | O45: Upper 95.0%
G46: Intercept | H46: 0.029679729 | I46: 0.028050981 | J46: 1.0580639 | K46: 0.31491522 | L46: -0.032821751 | M46: 0.092181209 | N46: -0.032821751 | O46: 0.092181209
...

Sheet F-F_Research_Data_Factors
A1: This file was created by CMPT_ME_BEME_RETS using the 202301 CRSP database.
A2: The 1-month TBill return is from Ibbotson and Associates Inc
A4: Month-Year | B4: Rm-Rf | C4: Rf
A5: 07-1926 | B5: 0.0296 | C5: 0.0022
A6: 08-1926 | B6: 0.0264 | C6: 0.0025
A7: 09-1926 | B7: 0.0036 | C7: 0.0023
A8: 10-1926 | B8: -0.0324 | C8: 0.0032 | E8: FAMA- FRENCH Research Data Factors
A9: 11-1926 | B9: 0.0253 | C9: 0.0031
A10: 12-1926 | B10: 0.0262 | C10: 0.0028 | E10: Dataset dowloaded from : http://mba.tuck.dartmouth.edu/pages/faculty/ken.french/data_library.html#Research
A11: 01-1927 | B11: -0.0006 | C11: 0.0025
A12: 02-1927 | B12: 0.0418 | C12: 0.0026
A13: 03-1927 | B13: 0.0013 | C13: 0.003
A14: 04-1927 | B14: 0.0046 | C14: 0.0025
A15: 05-1927 | B15: 0.0544 | C15: 0.003
A16: 06-1927 | B16: -0.0234 | C16: 0.0026
A17: 07-1927 | B17: 0.0726 | C17: 0.003
A18: 08-1927 | B18: 0.0197 | C18: 0.0028 | E18: Move down to the end for Annual Data on Rm - Rf
A19: 09-1927 | B19: 0.0476 | C19: 0.0021
A20: 10-1927 | B20: -0.0431 | C20: 0.0025
A21: 11-1927 | B21: 0.0658 | C21: 0.0021
A22: 12-1927 | B22: 0.0209 | C22: 0.0022
A23: 01-1928 | B23: -0.0068 | C23: 0.0025
A24: 02-1928 | B24: -0.017 | C24: 0.0033
A25: 03-1928 | B25: 0.0881 | C25: 0.0029
A26: 04-1928 | B26: 0.0423 | C26: 0.0022
A27: 05-1928 | B27: 0.0152 | C27: 0.0032
A28: 06-1928 | B28: -0.0485 | C28: 0.0031
A29: 07-1928 | B29: 0.0062 | C29: 0.0032
A30: 08-1928 | B30: 0.0668 | C30: 0.0032
... A1198: 12-2025 | B1198: -0.0036 | C1198: -0.0106
A1199: Annual Factors: January-December
A1201: Year | B1201: Rm-Rf | C1201: Rf
A1202: 1927 | B1202: 0.2947 | C1202: 0.0312
A1203: 1928 | B1203: 0.3539 | C1203: 0.0356
A1204: 1929 | B1204: -0.1954 | C1204: 0.0475
A1205: 1930 | B1205: -0.3123 | C1205: 0.0241
A1206: 1931 | B1206: -0.4511 | C1206: 0.0107
A1207: 1932 | B1207: -0.0939 | C1207: 0.0096
A1208: 1933 | B1208: 0.5705 | C1208: 0.003
A1209: 1934 | B1209: 0.0302 | C1209: 0.0016
...

Sheet Allocation
A1: Student ID | B1: XXXX | C1: XXXX Name | D1: YYYY | E1: YYYY Name
A2: 202020369 | B2: 52230 | C2: ROBERT HALF INTERNATIONAL INC | D2: 84819 | E2: M E R TELEMANAGEMENT SOLTNS LTD | G2: ONLY USE YOUR ALLOCATED COMPANIES (TICKERS) FOR YOUR ANALYSIS. | I2: =IF(B2=D2,"1","")
A3: 202011115 | B3: 21776 | C3: EXELON CORP | D3: 81013 | E3: TOWER SEMICONDUCTOR LTD | I3: =IF(B3=D3,"1","")
A4: 202002999 | B4: 77057 | C4: NATIONAL HEALTH INVESTORS INC | D4: 88841 | E4: RESOURCES CONNECTION INC | I4: =IF(B4=D4,"1","")
A5: 202016824 | B5: 23931 | C5: X C E L ENERGY INC | D5: 81254 | E5: INTERNATIONAL ASSETS HLDG CORP | I5: =IF(B5=D5,"1","")
A6: 202026658 | B6: 42877 | C6: HUNT J B TRANSPORT SERVICES INC | D6: 83762 | E6: HEMISPHERX BIOPHARMA INC | I6: =IF(B6=D6,"1","")
A7: 201971616 | B7: 78405 | C7: ROGERS COMMUNICATIONS INC | D7: 92690 | E7: UNITED MOBILE HOMES INC | I7: =IF(B7=D7,"1","")
A8: 202028690 | B8: 77920 | C8: BANCO LATINOAMERICANO DE EXP SA | D8: 89244 | E8: WEIGHT WATCHERS INTL INC NEW | G8: RENAME THE FIRST COMPANY (XXXX) TO THE FIRST TICKER AND THE SECOND (YYYY) TO THE SECOND TICKER IN YOUR SUMMARY REPORT | I8: =IF(B8=D8,"1","")
A9: 202006154 | B9: 74740 | C9: TAYLOR DEVICES INC | D9: 87162 | E9: 1 800 FLOWERS COM INC | I9: =IF(B9=D9,"1","")
A10: 201997060 | B10: 78002 | C10: TRINITY BIOTECH PLC | D10: 89258 | E10: PRUDENTIAL FINANCIAL INC | I10: =IF(B10=D10,"1","")
A11: 202023857 | B11: 57665 | C11: NIKE INC | D11: 85442 | E11: TAIWAN SEMICONDUCTOR MFG CO LTD | I11: =IF(B11=D11,"1","")
A12: 202020073 | B12: 77660 | C12: CREDIT ACCEPTANCE CORP | D12: 89167 | E12: CROSS COUNTRY INC | I12: =IF(B12=D12,"1","")
A13: 201938216 | B13: 77610 | C13: UNIVERSAL DISPLAY CORP | D13: 89129 | E13: ISHARES TRUST | I13: =IF(B13=D13,"1","")
A14: 202001307 | B14: 75070 | C14: WORLD FUEL SERVICES CORP | D14: 87318 | E14: EAGLE BANCORP INC | I14: =IF(B14=D14,"1","")
A15: 201966199 | B15: 49656 | C15: BANK NEW YORK INC | D15: 84519 | E15: CIENA CORP | I15: =IF(B15=D15,"1","")
A16: 201505630 | B16: 77239 | C16: CORPORATE OFFICE PROPERTIES TR | D16: 88953 | E16: A B B LTD | I16: =IF(B16=D16,"1","")
A17: 201931145 | B17: 56936 | C17: HANCOCK JOHN INCOME SECS TR | D17: 85418 | E17: CAMDEN NATIONAL CORP | I17: =IF(B17=D17,"1","")
A18: 202005711 | B18: 72864 | C18: UNIVERSAL HEALTH RLTY INCM TR | D18: 87084 | E18: P A S W INC | I18: =IF(B18=D18,"1","")
A19: 202008955 | B19: 48072 | C19: KOSS CORP | D19: 84372 | E19: N C R CORP NEW | I19: =IF(B19=D19,"1","")
A20: 202012673 | B20: 39642 | C20: BECTON DICKINSON & CO | D20: 83469 | E20: ARTESIAN RESOURCES CORP | I20: =IF(B20=D20,"1","")
... A122: 201621254 | B122: 10066 | C122: FRANKLIN TELECOMMUNICATIONS CORP | D122: 78690 | E122: INTASYS CORP | I122: =IF(B122=D122,"1","")
A123: 202001461 | B123: 76392 | C123: MERIT MEDICAL SYSTEMS INC | D123: 88406 | E123: ISHARES TRUST
A124: 201996252 | B124: 17478 | C124: MCGRAW HILL COS INC | D124: 80306 | E124: BIOCRYST PHARMACEUTICALS INC
A125: 201929364 | B125: 77528 | C125: S & T BANCORP INC | D125: 89060 | E125: ISHARES TRUST
A126: 201941246 | B126: 62367 | C126: GETTY REALTY CORP NEW | D126: 86080 | E126: ORTHODONTIX INC
A127: 202015351 | B127: 75905 | C127: G III APPAREL GROUP INC | D127: 88291 | E127: ISHARES TRUST
A128: 202004142 | B128: 75938 | C128: NEW GERMANY FUND INC | D128: 88295 | E128: ISHARES TRUST
A129: 201997886 | B129: 55597 | C129: BRUSH ENGINEERED MATERIALS INC | D129: 85299 | E129: LAKELAND FINANCIAL CORP
A130: 201653675 | B130: 75649 | C130: TREDEGAR CORP | D130: 88217 | E130: ISHARES TRUST
A131: 202001676 | B131: 55862 | C131: BIOMERICA INC | D131: 85339 | E131: MUNIHOLDINGS NEW YORK IN FD INC
A132: 201790811 | B132: 62930 | C132: MEXICO FUND INC | D132: 86102 | E132: FEDERATED INVESTORS INC PA
A133: 201968425 | B133: 11850 | C133: EXXON MOBIL CORP | D133: 79665 | E133: TEMPLETON EMERG MKTS INC FD INC
A134: 201932471 | B134: 36346 | C134: 1ST SOURCE CORP | D134: 83218 | E134: ISHARES INC
... A240: 202019679 | B240: 19828 | C240: TRIARC COMPANIES INC | D240: 80688 | E240: HIGHWOODS PROPERTIES INC
A241: THE TICKER PAIRS BELOW ARE SPARE AND ARE ONLY TO BE USED FOLLOWING AGREEMENT WITH THE MODULE LEADER | I241: =IF(#REF!=#REF!,"1","") -> #REF!
A242: SPARE1 | B242: 34497 | C242: NATIONAL PRESTO INDS INC | D242: 83120 | E242: COLUMBUS MCKINNON CORP NY | I242: =IF(B242=D242,"1","")
A243: SPARE2 | B243: 63765 | C243: SOUTHWESTERN ENERGY CO | D243: 86144 | E243: AMDOCS LTD | I243: =IF(B243=D243,"1","")
A244: SPARE3 | B244: 64282 | C244: LIMITED INC | D244: 86222 | E244: CREDIT SUISSE HIGH YIELD BOND FD | I244: =IF(B244=D244,"1","")
A245: SPARE4 | B245: 34666 | C245: CORNICHE GROUP INC | D245: 83124 | E245: C S G SYSTEMS INTERNATIONAL INC | I245: =IF(B245=D245,"1","")
A246: SPARE5 | B246: 77526 | C246: PEOPLES HOLDING CO | D246: 89059 | E246: ISHARES TRUST | I246: =IF(B246=#REF!,"1","") -> #REF!
...
